<?xml version="1.0"?>
<robot name="lidarbot">
    <material name="white">
        <color rgba="1 1 1 1" />
    </material>

    <material name="orange">
        <color rgba="1 0.3 0.1 1"/>
    </material>

    <material name="blue">
        <color rgba="0.2 0.2 1 1"/>
    </material>

    <material name="black">
        <color rgba="0 0 0 1"/>
    </material>
    
    <!-- BASE LINK -->
    <link name="base_link">

    </link>

    <!-- CHASSIS LINK -->

    <joint name="chassis_joint" type="fixed">
        <parent link="base_link"/>
        <child link="chassis"/>
        <origin xyz="0 0 0.02715"/>
    </joint>

    <link name="chassis">
        <visual>
            <geometry>
                <box size="0.255 0.15 0.034"/>
            </geometry>
            <material name="white"/>
        </visual>
        <collision>
            <geometry>
                <box size="0.255 0.15 0.034"/>
            </geometry>
        </collision>
    </link>
    
    <!-- Battery LINK -->

    <joint name="battery_joint" type="fixed">
        <parent link="base_link"/>
        <child link="battery"/>
        <origin xyz="-0.1435 0 0.0161"/>
    </joint>

    <link name="battery">
        <visual>
            <geometry>
                <box size="0.032 0.11 0.06"/>
            </geometry>
            <material name="orange"/>
        </visual>
        <collision>
            <geometry>
                <box size="0.032 0.11 0.06"/>
            </geometry>
        </collision>
    </link>
    
    <!-- LEFT FRONT WHEEL LINK -->

    <joint name="left_front_wheel_joint" type="continuous">
        <parent link="base_link"/>
        <child link="left_front_wheel"/>
        <origin xyz="0.0565 0.07 0" rpy="-1.5708 0 0"/>
        <axis xyz="0 0 1"/>
    </joint>

    <link name="left_front_wheel">
        <visual>
            <geometry>
                <cylinder radius="0.0339" length="0.025"/>
            </geometry>
            <material name="blue"/>
        </visual>
        <collision>
            <geometry>
                <cylinder radius="0.0339" length="0.025"/>
            </geometry>
        </collision>
    </link>

    <!-- RIGHT FRONT WHEEL LINK -->

    <joint name="right_front_wheel_joint" type="continuous">
        <parent link="base_link"/>
        <child link="right_front_wheel"/>
        <origin xyz="0.0565 -0.07 0" rpy="1.578 0 0"/>
        <axis xyz="0 0 -1"/>
    </joint>

    <link name="right_front_wheel">
        <visual>
            <geometry>
                <cylinder radius="0.0339" length="0.025"/>
            </geometry>
            <material name="blue"/>
        </visual>
        <collision>
            <geometry>
                <cylinder radius="0.0339" length="0.025"/>
            </geometry>
        </collision>
    </link>

    <!-- LEFT BACK WHEEL LINK -->

    <joint name="left_back_wheel_joint" type="continuous">
        <parent link="base_link"/>
        <child link="left_back_wheel"/>
        <origin xyz="-0.0565 0.07 0" rpy="-1.5708 0 0"/>
        <axis xyz="0 0 1"/>
    </joint>

    <link name="left_back_wheel">
        <visual>
            <geometry>
                <cylinder radius="0.0339" length="0.025"/>
            </geometry>
            <material name="blue"/>
        </visual>
        <collision>
            <geometry>
                <cylinder radius="0.0339" length="0.025"/>
            </geometry>
        </collision>
    </link>

    <!-- RIGHT BACK WHEEL LINK -->

    <joint name="right_back_wheel_joint" type="continuous">
        <parent link="base_link"/>
        <child link="right_back_wheel"/>
        <origin xyz="-0.0565 -0.07 0" rpy="1.5708 0 0"/>
        <axis xyz="0 0 -1"/>
    </joint>

    <link name="right_back_wheel">
        <visual>
            <geometry>
                <cylinder radius="0.0339" length="0.025"/>
            </geometry>
            <material name="blue"/>
        </visual>
        <collision>
            <geometry>
                <cylinder radius="0.0339" length="0.025"/>
            </geometry>
        </collision>
    </link>

    <!-- LIDAR LINK -->

    <joint name="laser_joint" type="fixed">
        <parent link="base_link"/>
        <child link="laser_frame"/>
        <origin xyz="0 0 .0706" rpy="0 0 0"/>
    </joint>

    <link name="laser_frame">
        <visual>
            <origin xyz="0 0 -0.0175"/>
            <geometry>
                <cylinder radius="0.035" length="0.053"/>
            </geometry>
            <material name="black"/>
        </visual>
        <collision>
            <geometry>
                <cylinder radius="0.035" length="0.053"/>
            </geometry>
        </collision>
    </link>
    
    <!-- IMU LINK -->

    <joint name="imu_joint" type="fixed">
        <parent link="base_link"/>
        <child link="imu"/>
        <origin xyz="0 -0.036 .025" rpy="0 0 0"/>
    </joint>

    <link name="imu">
        <visual>
            <origin xyz="0 0 0"/>
            <geometry>
                <box size="0.015 0.02 0.001"/>
            </geometry>
            <material name="orange"/>
        </visual>
        <collision>
            <geometry>
                <box size="0.015 0.02 0.001"/>
            </geometry>
        </collision>
    </link>

</robot>

